<!--URDF generated by ONSHAPE BY PTC INC, 1.216-->
<robot name="final">
    <link name="ge_27">
        <inertial>
            <mass value="8.25083e-07" />
            <origin xyz="3.20562e-09 1.10906e-05 -0.00439529" rpy="0 -0 0" />
            <inertia ixx="2.06105e-11" ixy="0" ixz="0" iyy="2.06174e-11" iyz="-6.23505e-14" izz="2.36834e-11" />
        </inertial>
        <visual>
            <origin xyz="0 0 0" rpy="0 -0 0" />
            <geometry>
                <mesh filename="package://final/meshes/GE_27.gltf" scale="1 1 1" />
            </geometry>
            <material name="0.098039_0.098039_0.098039_0.000000_0.000000">
                <color rgba="0.0980392 0.0980392 0.0980392 1" />
            </material>
        </visual>
    </link>
    <link name="ge_27_1">
        <inertial>
            <mass value="8.25083e-07" />
            <origin xyz="3.20562e-09 1.10906e-05 -0.00439529" rpy="0 -0 0" />
            <inertia ixx="2.06105e-11" ixy="0" ixz="0" iyy="2.06174e-11" iyz="-6.23505e-14" izz="2.36834e-11" />
        </inertial>
        <visual>
            <origin xyz="0 0 0" rpy="0 -0 0" />
            <geometry>
                <mesh filename="package://final/meshes/GE_27.gltf" scale="1 1 1" />
            </geometry>
            <material name="0.098039_0.098039_0.098039_0.000000_0.000000">
                <color rgba="0.0980392 0.0980392 0.0980392 1" />
            </material>
        </visual>
    </link>
    <link name="ge_27_2">
        <inertial>
            <mass value="8.25083e-07" />
            <origin xyz="3.20562e-09 1.10906e-05 -0.00439529" rpy="0 -0 0" />
            <inertia ixx="2.06105e-11" ixy="0" ixz="0" iyy="2.06174e-11" iyz="-6.23505e-14" izz="2.36834e-11" />
        </inertial>
        <visual>
            <origin xyz="0 0 0" rpy="0 -0 0" />
            <geometry>
                <mesh filename="package://final/meshes/GE_27.gltf" scale="1 1 1" />
            </geometry>
            <material name="0.098039_0.098039_0.098039_0.000000_0.000000">
                <color rgba="0.0980392 0.0980392 0.0980392 1" />
            </material>
        </visual>
    </link>
    <link name="ge_27_3">
        <inertial>
            <mass value="8.25083e-07" />
            <origin xyz="3.20562e-09 1.10906e-05 -0.00439529" rpy="0 -0 0" />
            <inertia ixx="2.06105e-11" ixy="0" ixz="0" iyy="2.06174e-11" iyz="-6.23505e-14" izz="2.36834e-11" />
        </inertial>
        <visual>
            <origin xyz="0 0 0" rpy="0 -0 0" />
            <geometry>
                <mesh filename="package://final/meshes/GE_27.gltf" scale="1 1 1" />
            </geometry>
            <material name="0.098039_0.098039_0.098039_0.000000_0.000000">
                <color rgba="0.0980392 0.0980392 0.0980392 1" />
            </material>
        </visual>
    </link>
    <link name="motor_1723_3">
        <inertial>
            <mass value="5.28583e-06" />
            <origin xyz="2.75404e-19 0.0114213 -2.15922e-21" rpy="0 -0 0" />
            <inertia ixx="3.33086e-10" ixy="0" ixz="0" iyy="1.89661e-10" iyz="0" izz="3.33092e-10" />
        </inertial>
        <visual>
            <origin xyz="0 0 0" rpy="0 -0 0" />
            <geometry>
                <mesh filename="package://final/meshes/MOTOR_1723_3.gltf" scale="1 1 1" />
            </geometry>
            <material name="0.098039_0.098039_0.098039_0.000000_0.000000">
                <color rgba="0.0980392 0.0980392 0.0980392 1" />
            </material>
        </visual>
    </link>
    <link name="motor_1723_3_1">
        <inertial>
            <mass value="5.28583e-06" />
            <origin xyz="2.75404e-19 0.0114213 -2.15922e-21" rpy="0 -0 0" />
            <inertia ixx="3.33086e-10" ixy="0" ixz="0" iyy="1.89661e-10" iyz="0" izz="3.33092e-10" />
        </inertial>
        <visual>
            <origin xyz="0 0 0" rpy="0 -0 0" />
            <geometry>
                <mesh filename="package://final/meshes/MOTOR_1723_3.gltf" scale="1 1 1" />
            </geometry>
            <material name="0.098039_0.098039_0.098039_0.000000_0.000000">
                <color rgba="0.0980392 0.0980392 0.0980392 1" />
            </material>
        </visual>
    </link>
    <link name="motor_1723_3_2">
        <inertial>
            <mass value="5.28583e-06" />
            <origin xyz="2.75404e-19 0.0114213 -2.15922e-21" rpy="0 -0 0" />
            <inertia ixx="3.33086e-10" ixy="0" ixz="0" iyy="1.89661e-10" iyz="0" izz="3.33092e-10" />
        </inertial>
        <visual>
            <origin xyz="0 0 0" rpy="0 -0 0" />
            <geometry>
                <mesh filename="package://final/meshes/MOTOR_1723_3.gltf" scale="1 1 1" />
            </geometry>
            <material name="0.098039_0.098039_0.098039_0.000000_0.000000">
                <color rgba="0.0980392 0.0980392 0.0980392 1" />
            </material>
        </visual>
    </link>
    <link name="motor_1723_3_3">
        <inertial>
            <mass value="5.28583e-06" />
            <origin xyz="2.75404e-19 0.0114213 -2.15922e-21" rpy="0 -0 0" />
            <inertia ixx="3.33086e-10" ixy="0" ixz="0" iyy="1.89661e-10" iyz="0" izz="3.33092e-10" />
        </inertial>
        <visual>
            <origin xyz="0 0 0" rpy="0 -0 0" />
            <geometry>
                <mesh filename="package://final/meshes/MOTOR_1723_3.gltf" scale="1 1 1" />
            </geometry>
            <material name="0.098039_0.098039_0.098039_0.000000_0.000000">
                <color rgba="0.0980392 0.0980392 0.0980392 1" />
            </material>
        </visual>
    </link>
    <link name="part_1">
        <inertial>
            <mass value="1.65711e-05" />
            <origin xyz="3.58501e-14 -0.000276944 -0.00394657" rpy="0 -0 0" />
            <inertia ixx="3.45031e-08" ixy="0" ixz="0" iyy="3.4501e-08" iyz="-4.2696e-11" izz="6.65929e-08" />
        </inertial>
        <visual>
            <origin xyz="0 0 0" rpy="0 -0 0" />
            <geometry>
                <mesh filename="package://final/meshes/Part_1.gltf" scale="1 1 1" />
            </geometry>
            <material name="0.615686_0.811765_0.929412_0.000000_0.000000">
                <color rgba="0.615686 0.811765 0.929412 1" />
            </material>
        </visual>
    </link>
    <link name="part_1_1">
        <inertial>
            <mass value="7.3421e-05" />
            <origin xyz="-0.015086 -2.13655e-18 0.0263909" rpy="0 -0 0" />
            <inertia ixx="5.11353e-08" ixy="0" ixz="-2.09097e-08" iyy="8.42073e-08" iyz="0" izz="4.31514e-08" />
        </inertial>
        <visual>
            <origin xyz="-0.02565 -2.56748e-18 0" rpy="0 -0 0" />
            <geometry>
                <mesh filename="package://final/meshes/Part_1_1.gltf" scale="1 1 1" />
            </geometry>
            <material name="0.901961_0.901961_0.901961_0.000000_0.000000">
                <color rgba="0.901961 0.901961 0.901961 1" />
            </material>
        </visual>
    </link>
    <link name="part_1_10">
        <inertial>
            <mass value="5.64431e-05" />
            <origin xyz="0.018582 -0.0564378 -0.007" rpy="0 -0 0" />
            <inertia ixx="7.17452e-08" ixy="-2.61091e-10" ixz="0" iyy="1.81356e-08" iyz="-9.33888e-10" izz="7.92819e-08" />
        </inertial>
        <visual>
            <origin xyz="0.0185 -0.083 -0.0215" rpy="0 -0 0" />
            <geometry>
                <mesh filename="package://final/meshes/Part_1_8.gltf" scale="1 1 1" />
            </geometry>
            <material name="0.615686_0.811765_0.929412_0.000000_0.000000">
                <color rgba="0.615686 0.811765 0.929412 1" />
            </material>
        </visual>
    </link>
    <link name="part_1_2">
        <inertial>
            <mass value="4.12078e-05" />
            <origin xyz="3.79361e-18 3.62892e-06 0.00425" rpy="0 -0 0" />
            <inertia ixx="8.51565e-08" ixy="0" ixz="0" iyy="8.51565e-08" iyz="0" izz="1.69817e-07" />
        </inertial>
        <visual>
            <origin xyz="0 -4.28626e-18 0" rpy="0 -0 0" />
            <geometry>
                <mesh filename="package://final/meshes/Part_1_2.gltf" scale="1 1 1" />
            </geometry>
            <material name="0.615686_0.811765_0.929412_0.000000_0.000000">
                <color rgba="0.615686 0.811765 0.929412 1" />
            </material>
        </visual>
    </link>
    <link name="part_1_3">
        <inertial>
            <mass value="2.34827e-05" />
            <origin xyz="-0.0552091 0.0302668 -0.00118083" rpy="0 -0 0" />
            <inertia ixx="3.39822e-08" ixy="0" ixz="0" iyy="3.31352e-08" iyz="8.12355e-11" izz="6.70369e-08" />
        </inertial>
        <visual>
            <origin xyz="-0.0552091 0.031875 -0.003" rpy="0 -0 0" />
            <geometry>
                <mesh filename="package://final/meshes/Part_1_3.gltf" scale="1 1 1" />
            </geometry>
            <material name="0.615686_0.811765_0.929412_0.000000_0.000000">
                <color rgba="0.615686 0.811765 0.929412 1" />
            </material>
        </visual>
    </link>
    <link name="part_1_4">
        <inertial>
            <mass value="5.15838e-05" />
            <origin xyz="-0.000955079 0.051074 0.00506434" rpy="0 -0 0" />
            <inertia ixx="3.61668e-08" ixy="-4.68961e-11" ixz="-2.59048e-10" iyy="3.91178e-08" iyz="3.80148e-12" izz="7.07688e-08" />
        </inertial>
        <visual>
            <origin xyz="0 0.05105 0" rpy="0 -0 0" />
            <geometry>
                <mesh filename="package://final/meshes/Part_1_4.gltf" scale="1 1 1" />
            </geometry>
            <material name="0.600000_0.580392_0.529412_0.000000_0.000000">
                <color rgba="0.6 0.580392 0.529412 1" />
            </material>
        </visual>
    </link>
    <link name="part_1_5">
        <inertial>
            <mass value="1.32509e-05" />
            <origin xyz="0.0188755 -6.7743e-18 -0.0238823" rpy="0 -0 0" />
            <inertia ixx="3.1991e-09" ixy="0" ixz="-8.3998e-11" iyy="7.06491e-09" iyz="0" izz="5.69039e-09" />
        </inertial>
        <visual>
            <origin xyz="0.0185 -1.73472e-18 -0.039" rpy="0 -0 0" />
            <geometry>
                <mesh filename="package://final/meshes/Part_1_5.gltf" scale="1 1 1" />
            </geometry>
            <material name="0.615686_0.811765_0.929412_0.000000_0.000000">
                <color rgba="0.615686 0.811765 0.929412 1" />
            </material>
        </visual>
    </link>
    <link name="part_1_6">
        <inertial>
            <mass value="7.69411e-06" />
            <origin xyz="7.85793e-05 4.12313e-18 0.0129894" rpy="0 -0 0" />
            <inertia ixx="1.97558e-09" ixy="0" ixz="-3.73989e-11" iyy="1.9032e-09" iyz="0" izz="2.09184e-09" />
        </inertial>
        <visual>
            <origin xyz="-1.73472e-18 5.86272e-19 0" rpy="0 -0 0" />
            <geometry>
                <mesh filename="package://final/meshes/Part_1_6.gltf" scale="1 1 1" />
            </geometry>
            <material name="0.615686_0.811765_0.929412_0.000000_0.000000">
                <color rgba="0.615686 0.811765 0.929412 1" />
            </material>
        </visual>
    </link>
    <link name="part_1_7">
        <inertial>
            <mass value="3.1104e-05" />
            <origin xyz="4.33063e-19 -1.73472e-18 0.0375" rpy="0 -0 0" />
            <inertia ixx="2.12592e-08" ixy="0" ixz="0" iyy="2.13373e-08" iyz="1.08551e-09" izz="6.64034e-09" />
        </inertial>
        <visual>
            <origin xyz="0 0.0145 0.0375" rpy="0 -0 0" />
            <geometry>
                <mesh filename="package://final/meshes/Part_1_7.gltf" scale="1 1 1" />
            </geometry>
            <material name="0.615686_0.811765_0.929412_0.000000_0.000000">
                <color rgba="0.615686 0.811765 0.929412 1" />
            </material>
        </visual>
    </link>
    <link name="part_1_8">
        <inertial>
            <mass value="7.69411e-06" />
            <origin xyz="-0.0159214 0.0105 0.0049894" rpy="0 -0 0" />
            <inertia ixx="1.97558e-09" ixy="0" ixz="-3.73989e-11" iyy="1.9032e-09" iyz="0" izz="2.09184e-09" />
        </inertial>
        <visual>
            <origin xyz="-0.016 0.0105 -0.008" rpy="0 -0 0" />
            <geometry>
                <mesh filename="package://final/meshes/Part_1_6.gltf" scale="1 1 1" />
            </geometry>
            <material name="0.615686_0.811765_0.929412_0.000000_0.000000">
                <color rgba="0.615686 0.811765 0.929412 1" />
            </material>
        </visual>
    </link>
    <link name="part_1_9">
        <inertial>
            <mass value="7.69411e-06" />
            <origin xyz="7.85793e-05 4.12313e-18 0.0129894" rpy="0 -0 0" />
            <inertia ixx="1.97558e-09" ixy="0" ixz="-3.73989e-11" iyy="1.9032e-09" iyz="0" izz="2.09184e-09" />
        </inertial>
        <visual>
            <origin xyz="-1.73472e-18 5.86272e-19 0" rpy="0 -0 0" />
            <geometry>
                <mesh filename="package://final/meshes/Part_1_6.gltf" scale="1 1 1" />
            </geometry>
            <material name="0.615686_0.811765_0.929412_0.000000_0.000000">
                <color rgba="0.615686 0.811765 0.929412 1" />
            </material>
        </visual>
    </link>
    <link name="part_2">
        <inertial>
            <mass value="3.33193e-05" />
            <origin xyz="-8.64337e-19 -3.95104e-19 -0.00425" rpy="0 -0 0.45282" />
            <inertia ixx="4.34189e-08" ixy="0" ixz="0" iyy="4.34189e-08" iyz="0" izz="8.64367e-08" />
        </inertial>
        <visual>
            <origin xyz="2.52269e-18 -4.01196e-18 -0.0085" rpy="0 -0 0.45282" />
            <geometry>
                <mesh filename="package://final/meshes/Part_2.gltf" scale="1 1 1" />
            </geometry>
            <material name="0.647059_0.647059_0.647059_0.000000_0.000000">
                <color rgba="0.647059 0.647059 0.647059 1" />
            </material>
        </visual>
    </link>
    <link name="pcb_chazuo_92">
        <inertial>
            <mass value="1.23799e-06" />
            <origin xyz="-0.0157216 -0.0156448 5.98461e-05" rpy="0 -0 0" />
            <inertia ixx="5.01717e-11" ixy="9.01076e-12" ixz="-4.40144e-14" iyy="1.02983e-10" iyz="-1.29268e-13" izz="6.45786e-11" />
        </inertial>
        <visual>
            <origin xyz="0 0 0" rpy="0 -0 0" />
            <geometry>
                <mesh filename="package://final/meshes/PCB_CHAZUO_92.gltf" scale="1 1 1" />
            </geometry>
            <material name="0.098039_0.098039_0.098039_0.000000_0.000000">
                <color rgba="0.0980392 0.0980392 0.0980392 1" />
            </material>
        </visual>
    </link>
    <link name="pcb_chazuo_92_1">
        <inertial>
            <mass value="1.23799e-06" />
            <origin xyz="-0.0157216 -0.0156448 5.98461e-05" rpy="0 -0 0" />
            <inertia ixx="5.01717e-11" ixy="9.01076e-12" ixz="-4.40144e-14" iyy="1.02983e-10" iyz="-1.29268e-13" izz="6.45786e-11" />
        </inertial>
        <visual>
            <origin xyz="0 0 0" rpy="0 -0 0" />
            <geometry>
                <mesh filename="package://final/meshes/PCB_CHAZUO_92.gltf" scale="1 1 1" />
            </geometry>
            <material name="0.098039_0.098039_0.098039_0.000000_0.000000">
                <color rgba="0.0980392 0.0980392 0.0980392 1" />
            </material>
        </visual>
    </link>
    <link name="pcb_chazuo_92_2">
        <inertial>
            <mass value="1.23799e-06" />
            <origin xyz="-0.0157216 -0.0156448 5.98461e-05" rpy="0 -0 0" />
            <inertia ixx="5.01717e-11" ixy="9.01076e-12" ixz="-4.40144e-14" iyy="1.02983e-10" iyz="-1.29268e-13" izz="6.45786e-11" />
        </inertial>
        <visual>
            <origin xyz="0 0 0" rpy="0 -0 0" />
            <geometry>
                <mesh filename="package://final/meshes/PCB_CHAZUO_92.gltf" scale="1 1 1" />
            </geometry>
            <material name="0.098039_0.098039_0.098039_0.000000_0.000000">
                <color rgba="0.0980392 0.0980392 0.0980392 1" />
            </material>
        </visual>
    </link>
    <link name="pcb_chazuo_92_3">
        <inertial>
            <mass value="1.23799e-06" />
            <origin xyz="-0.0157216 -0.0156448 5.98461e-05" rpy="0 -0 0" />
            <inertia ixx="5.01717e-11" ixy="9.01076e-12" ixz="-4.40144e-14" iyy="1.02983e-10" iyz="-1.29268e-13" izz="6.45786e-11" />
        </inertial>
        <visual>
            <origin xyz="0 0 0" rpy="0 -0 0" />
            <geometry>
                <mesh filename="package://final/meshes/PCB_CHAZUO_92.gltf" scale="1 1 1" />
            </geometry>
            <material name="0.098039_0.098039_0.098039_0.000000_0.000000">
                <color rgba="0.0980392 0.0980392 0.0980392 1" />
            </material>
        </visual>
    </link>
    <link name="root" />
    <link name="sg_ziji_15">
        <inertial>
            <mass value="8.52654e-06" />
            <origin xyz="-0.0154974 -0.00451431 -0.0102514" rpy="0 -0 0" />
            <inertia ixx="4.61006e-10" ixy="-3.34825e-11" ixz="-1.13152e-13" iyy="1.77029e-09" iyz="3.49898e-14" izz="1.41048e-09" />
        </inertial>
        <visual>
            <origin xyz="-0.0035 -0.0064 -0.01025" rpy="0 -0 0" />
            <geometry>
                <mesh filename="package://final/meshes/SG_ZIJI_15.gltf" scale="1 1 1" />
            </geometry>
            <material name="0.098039_0.098039_0.098039_0.000000_0.000000">
                <color rgba="0.0980392 0.0980392 0.0980392 1" />
            </material>
        </visual>
    </link>
    <link name="sg_ziji_15_1">
        <inertial>
            <mass value="8.52654e-06" />
            <origin xyz="0.0135026 -0.00291431 -1.41291e-06" rpy="0 -0 0" />
            <inertia ixx="4.61006e-10" ixy="-3.34825e-11" ixz="-1.13152e-13" iyy="1.77029e-09" iyz="3.49898e-14" izz="1.41048e-09" />
        </inertial>
        <visual>
            <origin xyz="0.0255 -0.0048 1.01455e-34" rpy="0 -0 0" />
            <geometry>
                <mesh filename="package://final/meshes/SG_ZIJI_15.gltf" scale="1 1 1" />
            </geometry>
            <material name="0.098039_0.098039_0.098039_0.000000_0.000000">
                <color rgba="0.0980392 0.0980392 0.0980392 1" />
            </material>
        </visual>
    </link>
    <link name="sg_ziji_15_2">
        <inertial>
            <mass value="8.52654e-06" />
            <origin xyz="-0.0154974 -0.00451431 -0.0102514" rpy="0 -0 0" />
            <inertia ixx="4.61006e-10" ixy="-3.34825e-11" ixz="-1.13152e-13" iyy="1.77029e-09" iyz="3.49898e-14" izz="1.41048e-09" />
        </inertial>
        <visual>
            <origin xyz="-0.0035 -0.0064 -0.01025" rpy="0 -0 0" />
            <geometry>
                <mesh filename="package://final/meshes/SG_ZIJI_15.gltf" scale="1 1 1" />
            </geometry>
            <material name="0.098039_0.098039_0.098039_0.000000_0.000000">
                <color rgba="0.0980392 0.0980392 0.0980392 1" />
            </material>
        </visual>
    </link>
    <link name="sg_ziji_15_3">
        <inertial>
            <mass value="8.52654e-06" />
            <origin xyz="-0.0119974 0.00188569 -1.41291e-06" rpy="0 -0 0" />
            <inertia ixx="4.61006e-10" ixy="-3.34825e-11" ixz="-1.13152e-13" iyy="1.77029e-09" iyz="3.49898e-14" izz="1.41048e-09" />
        </inertial>
        <visual>
            <origin xyz="0 0 0" rpy="0 -0 0" />
            <geometry>
                <mesh filename="package://final/meshes/SG_ZIJI_15.gltf" scale="1 1 1" />
            </geometry>
            <material name="0.098039_0.098039_0.098039_0.000000_0.000000">
                <color rgba="0.0980392 0.0980392 0.0980392 1" />
            </material>
        </visual>
    </link>
    <link name="xg_ziji_16">
        <inertial>
            <mass value="1.11279e-05" />
            <origin xyz="-0.0128222 -0.0193102 2.62129e-07" rpy="0 -0 0" />
            <inertia ixx="6.76436e-10" ixy="1.80035e-11" ixz="-6.15782e-14" iyy="2.43923e-09" iyz="1.06955e-14" izz="1.99262e-09" />
        </inertial>
        <visual>
            <origin xyz="0 0 0" rpy="0 -0 0" />
            <geometry>
                <mesh filename="package://final/meshes/XG_ZIJI_16.gltf" scale="1 1 1" />
            </geometry>
            <material name="0.098039_0.098039_0.098039_0.000000_0.000000">
                <color rgba="0.0980392 0.0980392 0.0980392 1" />
            </material>
        </visual>
    </link>
    <link name="xg_ziji_16_1">
        <inertial>
            <mass value="1.11279e-05" />
            <origin xyz="-0.0128222 -0.0193102 2.62129e-07" rpy="0 -0 0" />
            <inertia ixx="6.76436e-10" ixy="1.80035e-11" ixz="-6.15782e-14" iyy="2.43923e-09" iyz="1.06955e-14" izz="1.99262e-09" />
        </inertial>
        <visual>
            <origin xyz="0 0 0" rpy="0 -0 0" />
            <geometry>
                <mesh filename="package://final/meshes/XG_ZIJI_16.gltf" scale="1 1 1" />
            </geometry>
            <material name="0.098039_0.098039_0.098039_0.000000_0.000000">
                <color rgba="0.0980392 0.0980392 0.0980392 1" />
            </material>
        </visual>
    </link>
    <link name="xg_ziji_16_2">
        <inertial>
            <mass value="1.11279e-05" />
            <origin xyz="-0.0128222 -0.0193102 2.62129e-07" rpy="0 -0 0" />
            <inertia ixx="6.76436e-10" ixy="1.80035e-11" ixz="-6.15782e-14" iyy="2.43923e-09" iyz="1.06955e-14" izz="1.99262e-09" />
        </inertial>
        <visual>
            <origin xyz="0 0 0" rpy="0 -0 0" />
            <geometry>
                <mesh filename="package://final/meshes/XG_ZIJI_16.gltf" scale="1 1 1" />
            </geometry>
            <material name="0.098039_0.098039_0.098039_0.000000_0.000000">
                <color rgba="0.0980392 0.0980392 0.0980392 1" />
            </material>
        </visual>
    </link>
    <link name="xg_ziji_16_3">
        <inertial>
            <mass value="1.11279e-05" />
            <origin xyz="-0.0200722 0.00628976 -0.0102497" rpy="0 -0 0" />
            <inertia ixx="6.76436e-10" ixy="1.80035e-11" ixz="-6.15782e-14" iyy="2.43923e-09" iyz="1.06955e-14" izz="1.99262e-09" />
        </inertial>
        <visual>
            <origin xyz="-0.00725 0.0256 -0.01025" rpy="0 -0 0" />
            <geometry>
                <mesh filename="package://final/meshes/XG_ZIJI_16.gltf" scale="1 1 1" />
            </geometry>
            <material name="0.098039_0.098039_0.098039_0.000000_0.000000">
                <color rgba="0.0980392 0.0980392 0.0980392 1" />
            </material>
        </visual>
    </link>
    <link name="zk_122">
        <inertial>
            <mass value="1.42533e-05" />
            <origin xyz="-0.012873 -0.00769104 4.08355e-06" rpy="0 -0 0" />
            <inertia ixx="9.16288e-10" ixy="1.8882e-12" ixz="-8.47469e-13" iyy="3.11271e-09" iyz="3.98608e-13" izz="2.59629e-09" />
        </inertial>
        <visual>
            <origin xyz="0 0 0" rpy="0 -0 0" />
            <geometry>
                <mesh filename="package://final/meshes/ZK_122.gltf" scale="1 1 1" />
            </geometry>
            <material name="0.098039_0.098039_0.098039_0.000000_0.000000">
                <color rgba="0.0980392 0.0980392 0.0980392 1" />
            </material>
        </visual>
    </link>
    <link name="zk_122_1">
        <inertial>
            <mass value="1.42533e-05" />
            <origin xyz="-0.012873 -0.00769104 4.08355e-06" rpy="0 -0 0" />
            <inertia ixx="9.16288e-10" ixy="1.8882e-12" ixz="-8.47469e-13" iyy="3.11271e-09" iyz="3.98608e-13" izz="2.59629e-09" />
        </inertial>
        <visual>
            <origin xyz="0 0 0" rpy="0 -0 0" />
            <geometry>
                <mesh filename="package://final/meshes/ZK_122.gltf" scale="1 1 1" />
            </geometry>
            <material name="0.098039_0.098039_0.098039_0.000000_0.000000">
                <color rgba="0.0980392 0.0980392 0.0980392 1" />
            </material>
        </visual>
    </link>
    <link name="zk_122_2">
        <inertial>
            <mass value="1.42533e-05" />
            <origin xyz="-0.012873 -0.00769104 4.08355e-06" rpy="0 -0 0" />
            <inertia ixx="9.16288e-10" ixy="1.8882e-12" ixz="-8.47469e-13" iyy="3.11271e-09" iyz="3.98608e-13" izz="2.59629e-09" />
        </inertial>
        <visual>
            <origin xyz="0 0 0" rpy="0 -0 0" />
            <geometry>
                <mesh filename="package://final/meshes/ZK_122.gltf" scale="1 1 1" />
            </geometry>
            <material name="0.098039_0.098039_0.098039_0.000000_0.000000">
                <color rgba="0.0980392 0.0980392 0.0980392 1" />
            </material>
        </visual>
    </link>
    <link name="zk_122_3">
        <inertial>
            <mass value="1.42533e-05" />
            <origin xyz="-0.012873 -0.00769104 4.08355e-06" rpy="0 -0 0" />
            <inertia ixx="9.16288e-10" ixy="1.8882e-12" ixz="-8.47469e-13" iyy="3.11271e-09" iyz="3.98608e-13" izz="2.59629e-09" />
        </inertial>
        <visual>
            <origin xyz="0 0 0" rpy="0 -0 0" />
            <geometry>
                <mesh filename="package://final/meshes/ZK_122.gltf" scale="1 1 1" />
            </geometry>
            <material name="0.098039_0.098039_0.098039_0.000000_0.000000">
                <color rgba="0.0980392 0.0980392 0.0980392 1" />
            </material>
        </visual>
    </link>
    <link name="金属舵盘_从动__v2">
        <inertial>
            <mass value="5.66049e-07" />
            <origin xyz="4.33681e-19 0.00213361 3.46945e-18" rpy="3.14159 1.45364 3.14159" />
            <inertia ixx="1.39403e-11" ixy="0" ixz="0" iyy="2.72486e-11" iyz="0" izz="1.39403e-11" />
        </inertial>
        <visual>
            <origin xyz="0.00116886 0.02515 0.00993145" rpy="3.14159 1.45364 3.14159" />
            <geometry>
                <mesh filename="package://final/meshes/_________v2.gltf" scale="1 1 1" />
            </geometry>
            <material name="0.960784_0.960784_0.964706_0.000000_0.000000">
                <color rgba="0.960784 0.960784 0.964706 1" />
            </material>
        </visual>
    </link>
    <link name="金属舵盘_从动__v2_1">
        <inertial>
            <mass value="5.66049e-07" />
            <origin xyz="4.33681e-19 0.00213361 3.46945e-18" rpy="3.14159 1.45364 3.14159" />
            <inertia ixx="1.39403e-11" ixy="0" ixz="0" iyy="2.72486e-11" iyz="0" izz="1.39403e-11" />
        </inertial>
        <visual>
            <origin xyz="0.00116886 0.02515 0.00993145" rpy="3.14159 1.45364 3.14159" />
            <geometry>
                <mesh filename="package://final/meshes/_________v2.gltf" scale="1 1 1" />
            </geometry>
            <material name="0.960784_0.960784_0.964706_0.000000_0.000000">
                <color rgba="0.960784 0.960784 0.964706 1" />
            </material>
        </visual>
    </link>
    <link name="金属舵盘_从动__v2_2">
        <inertial>
            <mass value="5.66049e-07" />
            <origin xyz="4.33681e-19 0.00213361 3.46945e-18" rpy="3.14159 1.45364 3.14159" />
            <inertia ixx="1.39403e-11" ixy="0" ixz="0" iyy="2.72486e-11" iyz="0" izz="1.39403e-11" />
        </inertial>
        <visual>
            <origin xyz="0.00116886 0.02515 0.00993145" rpy="3.14159 1.45364 3.14159" />
            <geometry>
                <mesh filename="package://final/meshes/_________v2.gltf" scale="1 1 1" />
            </geometry>
            <material name="0.960784_0.960784_0.964706_0.000000_0.000000">
                <color rgba="0.960784 0.960784 0.964706 1" />
            </material>
        </visual>
    </link>
    <link name="金属舵盘_从动__v2_3">
        <inertial>
            <mass value="5.66049e-07" />
            <origin xyz="4.33681e-19 0.00213361 3.46945e-18" rpy="3.14159 1.45364 3.14159" />
            <inertia ixx="1.39403e-11" ixy="0" ixz="0" iyy="2.72486e-11" iyz="0" izz="1.39403e-11" />
        </inertial>
        <visual>
            <origin xyz="0.00116886 0.02515 0.00993145" rpy="3.14159 1.45364 3.14159" />
            <geometry>
                <mesh filename="package://final/meshes/_________v2.gltf" scale="1 1 1" />
            </geometry>
            <material name="0.960784_0.960784_0.964706_0.000000_0.000000">
                <color rgba="0.960784 0.960784 0.964706 1" />
            </material>
        </visual>
    </link>
    <link name="金属舵盘_驱动__v2">
        <inertial>
            <mass value="7.57429e-07" />
            <origin xyz="2.51545e-13 0.0028975 4.41713e-14" rpy="3.14159 -1.56583 3.14159" />
            <inertia ixx="1.73052e-11" ixy="0" ixz="0" iyy="3.28036e-11" iyz="0" izz="1.73052e-11" />
        </inertial>
        <visual>
            <origin xyz="4.96729e-05 -0.0225 -0.00999988" rpy="3.14159 -1.56583 3.14159" />
            <geometry>
                <mesh filename="package://final/meshes/_________v2_1.gltf" scale="1 1 1" />
            </geometry>
            <material name="0.960784_0.960784_0.964706_0.000000_0.000000">
                <color rgba="0.960784 0.960784 0.964706 1" />
            </material>
        </visual>
    </link>
    <link name="金属舵盘_驱动__v2_1">
        <inertial>
            <mass value="7.57429e-07" />
            <origin xyz="4.29205e-14 -0.0016025 -0.007" rpy="0 -0 0" />
            <inertia ixx="1.73052e-11" ixy="0" ixz="0" iyy="3.28036e-11" iyz="0" izz="1.73052e-11" />
        </inertial>
        <visual>
            <origin xyz="-0.01 -0.027 -0.007" rpy="0 -0 0" />
            <geometry>
                <mesh filename="package://final/meshes/_________v2_1.gltf" scale="1 1 1" />
            </geometry>
            <material name="0.960784_0.960784_0.964706_0.000000_0.000000">
                <color rgba="0.960784 0.960784 0.964706 1" />
            </material>
        </visual>
    </link>
    <link name="金属舵盘_驱动__v2_2">
        <inertial>
            <mass value="7.57429e-07" />
            <origin xyz="2.51545e-13 0.0028975 4.41713e-14" rpy="3.14159 -1.56583 3.14159" />
            <inertia ixx="1.73052e-11" ixy="0" ixz="0" iyy="3.28036e-11" iyz="0" izz="1.73052e-11" />
        </inertial>
        <visual>
            <origin xyz="4.96729e-05 -0.0225 -0.00999988" rpy="3.14159 -1.56583 3.14159" />
            <geometry>
                <mesh filename="package://final/meshes/_________v2_1.gltf" scale="1 1 1" />
            </geometry>
            <material name="0.960784_0.960784_0.964706_0.000000_0.000000">
                <color rgba="0.960784 0.960784 0.964706 1" />
            </material>
        </visual>
    </link>
    <link name="金属舵盘_驱动__v2_3">
        <inertial>
            <mass value="7.57429e-07" />
            <origin xyz="2.51545e-13 0.0028975 4.41713e-14" rpy="3.14159 -1.56583 3.14159" />
            <inertia ixx="1.73052e-11" ixy="0" ixz="0" iyy="3.28036e-11" iyz="0" izz="1.73052e-11" />
        </inertial>
        <visual>
            <origin xyz="4.96729e-05 -0.0225 -0.00999988" rpy="3.14159 -1.56583 3.14159" />
            <geometry>
                <mesh filename="package://final/meshes/_________v2_1.gltf" scale="1 1 1" />
            </geometry>
            <material name="0.960784_0.960784_0.964706_0.000000_0.000000">
                <color rgba="0.960784 0.960784 0.964706 1" />
            </material>
        </visual>
    </link>
    <joint name="fastened_1" type="fixed">
        <origin xyz="0.029 0.0016 0.01025" rpy="-1.5708 -6.10623e-16 1.5708" />
        <axis xyz="-1 -2.39272e-16 -0" />
        <parent link="sg_ziji_15_1" />
        <child link="part_1_8" />
    </joint>
    <joint name="fastened_16" type="fixed">
        <origin xyz="0 5.20417e-18 0.003" rpy="8.23152e-34 1.41322e-32 5.81648e-66" />
        <axis xyz="0 0 -1" />
        <parent link="part_1" />
        <child link="part_1_2" />
    </joint>
    <joint name="fastened_1_1" type="fixed">
        <origin xyz="5.20417e-18 1.38778e-17 0.075" rpy="3.46945e-18 9.48586e-19 -9.49068e-19" />
        <axis xyz="0 0 -1" />
        <parent link="part_1_7" />
        <child link="part_1_6" />
    </joint>
    <joint name="fastened_1_2" type="fixed">
        <origin xyz="0.045905 0.0223345 2.77556e-17" rpy="1.11253e-31 5.83622e-31 2.02362" />
        <axis xyz="0 0 -1" />
        <parent link="part_2" />
        <child link="part_1_4" />
    </joint>
    <joint name="fastened_1_3" type="fixed">
        <origin xyz="0.0185 -0.118 -0.007" rpy="1.5708 6.80754e-16 1.23573e-15" />
        <axis xyz="0 0 -1" />
        <parent link="part_1_10" />
        <child link="part_1_9" />
    </joint>
    <joint name="fastened_2" type="fixed">
        <origin xyz="-0.016 0.0105 -0.008" rpy="3.14159 -1.75264e-16 -8.00951e-17" />
        <axis xyz="1.92747e-16 -0 -1" />
        <parent link="part_1_8" />
        <child link="part_1_7" />
    </joint>
    <joint name="fastened_2_1" type="fixed">
        <origin xyz="0.016 -0.0105 0.008" rpy="0 1.5708 4.71239" />
        <axis xyz="0 1 0" />
        <parent link="part_1_6" />
        <child link="sg_ziji_15" />
    </joint>
    <joint name="fastened_2_2" type="fixed">
        <origin xyz="0.0185 -1.38778e-17 -0.039" rpy="-3.14159 3.34999e-17 1.11231e-16" />
        <axis xyz="0 0 -1" />
        <parent link="part_1_5" />
        <child link="part_1_1" />
    </joint>
    <joint name="fastened_3" type="fixed">
        <origin xyz="-0.01825 0.05105 0.027" rpy="-2.60949e-15 4.38492e-15 1.5708" />
        <axis xyz="0 1 0" />
        <parent link="part_1_4" />
        <child link="金属舵盘_驱动__v2_1" />
    </joint>
    <joint name="fastened_4" type="fixed">
        <origin xyz="-0.00699992 0.0045 -3.47711e-05" rpy="1.57576 -0 -1.5708" />
        <axis xyz="1 0 0" />
        <parent link="金属舵盘_驱动__v2" />
        <child link="part_1_10" />
    </joint>
    <joint name="fastened_5" type="fixed">
        <origin xyz="0.016 -0.0105 0.008" rpy="0 1.5708 -1.5708" />
        <axis xyz="0 1 0" />
        <parent link="part_1_9" />
        <child link="sg_ziji_15_2" />
    </joint>
    <joint name="fastened_6" type="fixed">
        <origin xyz="0.00699992 0.0045 3.47711e-05" rpy="-1.56583 -6.10623e-16 -1.5708" />
        <axis xyz="1 2.39272e-16 0" />
        <parent link="金属舵盘_驱动__v2_2" />
        <child link="part_1_5" />
    </joint>
    <joint name="fastened_7" type="fixed">
        <origin xyz="0.0552091 -0.032625 -0.0265" rpy="-8.62589e-32 4.24346e-32 1.07726e-15" />
        <axis xyz="0 0 1" />
        <parent link="part_1" />
        <child link="part_1_3" />
    </joint>
    <joint name="fastened_8" type="fixed">
        <origin xyz="-0.0654591 -0.000875 0.003" rpy="1.5708 -1.07137e-14 -1.5708" />
        <axis xyz="0 -1 0" />
        <parent link="part_1_3" />
        <child link="xg_ziji_16_3" />
    </joint>
    <joint name="fixed_node_to_root_joint" type="fixed">
        <origin xyz="-0.0505037 -0.0113203 -0.124523" rpy="0 -0 0.00746939" />
        <axis xyz="0 0 1" />
        <parent link="root" />
        <child link="part_1" />
    </joint>
    <joint name="group_1_fastened_joint" type="fixed">
        <origin xyz="-0.00125 0.02285 0" rpy="0 -1.5708 -3.60822e-16" />
        <axis xyz="0 0 1" />
        <parent link="motor_1723_3_3" />
        <child link="pcb_chazuo_92_3" />
    </joint>
    <joint name="group_1_fastened_joint_1" type="fixed">
        <origin xyz="-0.0255 -0.006 -1.59595e-16" rpy="1.5708 2.23857e-16 -9.12723e-16" />
        <axis xyz="0 0 1" />
        <parent link="pcb_chazuo_92_3" />
        <child link="ge_27_3" />
    </joint>
    <joint name="group_1_fastened_joint_10" type="fixed">
        <origin xyz="-0.00125 0.02285 1.249e-16" rpy="0 -1.5708 5.24102e-17" />
        <axis xyz="0 0 1" />
        <parent link="motor_1723_3_1" />
        <child link="pcb_chazuo_92_1" />
    </joint>
    <joint name="group_1_fastened_joint_11" type="fixed">
        <origin xyz="-0.0255 -0.006 -5.27356e-16" rpy="1.5708 2.53043e-16 -9.85599e-16" />
        <axis xyz="0 0 1" />
        <parent link="pcb_chazuo_92_1" />
        <child link="ge_27_1" />
    </joint>
    <joint name="group_1_fastened_joint_12" type="fixed">
        <origin xyz="0.0255 -0.0048 6.93889e-18" rpy="2.56816e-17 -3.46945e-18 1.98248e-18" />
        <axis xyz="-0 -0 -1" />
        <parent link="sg_ziji_15_1" />
        <child link="zk_122_1" />
    </joint>
    <joint name="group_1_fastened_joint_13" type="fixed">
        <origin xyz="-1.11022e-16 -0.02285 -0.00125" rpy="0 1.5708 6.5922e-18" />
        <axis xyz="0 0 1" />
        <parent link="xg_ziji_16_1" />
        <child link="motor_1723_3_1" />
    </joint>
    <joint name="group_1_fastened_joint_14" type="fixed">
        <origin xyz="0.0255 -0.0048 6.93889e-18" rpy="2.56816e-17 -3.46945e-18 1.98248e-18" />
        <axis xyz="0 0 1" />
        <parent link="sg_ziji_15_1" />
        <child link="xg_ziji_16_1" />
    </joint>
    <joint name="group_1_fastened_joint_15" type="fixed">
        <origin xyz="-0.00125 0.02285 1.94289e-16" rpy="0 -1.5708 -8.892e-16" />
        <axis xyz="0 0 1" />
        <parent link="motor_1723_3" />
        <child link="pcb_chazuo_92" />
    </joint>
    <joint name="group_1_fastened_joint_16" type="fixed">
        <origin xyz="-0.0255 -0.006 -5.27356e-16" rpy="1.5708 3.14455e-16 -7.99234e-16" />
        <axis xyz="0 0 1" />
        <parent link="pcb_chazuo_92" />
        <child link="ge_27" />
    </joint>
    <joint name="group_1_fastened_joint_17" type="fixed">
        <origin xyz="-0.0035 -0.0064 -0.01025" rpy="5.48765e-19 3.46945e-18 -3.35395e-19" />
        <axis xyz="-0 -0 -1" />
        <parent link="sg_ziji_15" />
        <child link="zk_122" />
    </joint>
    <joint name="group_1_fastened_joint_18" type="fixed">
        <origin xyz="-1.94289e-16 -0.02285 -0.00125" rpy="0 1.5708 6.15404e-18" />
        <axis xyz="0 0 1" />
        <parent link="xg_ziji_16" />
        <child link="motor_1723_3" />
    </joint>
    <joint name="group_1_fastened_joint_19" type="fixed">
        <origin xyz="-0.0035 -0.0064 -0.01025" rpy="5.48765e-19 3.46945e-18 -3.35395e-19" />
        <axis xyz="0 0 1" />
        <parent link="sg_ziji_15" />
        <child link="xg_ziji_16" />
    </joint>
    <joint name="group_1_fastened_joint_2" type="fixed">
        <origin xyz="-6.93889e-18 1.38778e-17 0" rpy="-7.22224e-34 2.58534e-29 -1.41605e-32" />
        <axis xyz="-0 -0 -1" />
        <parent link="sg_ziji_15_3" />
        <child link="zk_122_3" />
    </joint>
    <joint name="group_1_fastened_joint_3" type="fixed">
        <origin xyz="-0.00725 0.00275 -0.0115" rpy="0 1.5708 1.58315e-17" />
        <axis xyz="0 0 1" />
        <parent link="xg_ziji_16_3" />
        <child link="motor_1723_3_3" />
    </joint>
    <joint name="group_1_fastened_joint_4" type="fixed">
        <origin xyz="-0.00725 0.0256 -0.01025" rpy="-7.22224e-34 2.58534e-29 -1.41605e-32" />
        <axis xyz="-0 -0 -1" />
        <parent link="xg_ziji_16_3" />
        <child link="sg_ziji_15_3" />
    </joint>
    <joint name="group_1_fastened_joint_5" type="fixed">
        <origin xyz="-0.00125 0.02285 -9.71445e-17" rpy="0 -1.5708 -1.63858e-16" />
        <axis xyz="0 0 1" />
        <parent link="motor_1723_3_2" />
        <child link="pcb_chazuo_92_2" />
    </joint>
    <joint name="group_1_fastened_joint_6" type="fixed">
        <origin xyz="-0.0255 -0.006 -2.91434e-16" rpy="1.5708 5.05564e-16 -2.14339e-16" />
        <axis xyz="0 0 1" />
        <parent link="pcb_chazuo_92_2" />
        <child link="ge_27_2" />
    </joint>
    <joint name="group_1_fastened_joint_7" type="fixed">
        <origin xyz="-0.0035 -0.0064 -0.01025" rpy="7.57861e-19 -1.73472e-18 8.2713e-18" />
        <axis xyz="-0 -0 -1" />
        <parent link="sg_ziji_15_2" />
        <child link="zk_122_2" />
    </joint>
    <joint name="group_1_fastened_joint_8" type="fixed">
        <origin xyz="9.71445e-17 -0.02285 -0.00125" rpy="0 1.5708 1.2263e-16" />
        <axis xyz="0 0 1" />
        <parent link="xg_ziji_16_2" />
        <child link="motor_1723_3_2" />
    </joint>
    <joint name="group_1_fastened_joint_9" type="fixed">
        <origin xyz="-0.0035 -0.0064 -0.01025" rpy="7.57861e-19 -1.73472e-18 8.2713e-18" />
        <axis xyz="0 0 1" />
        <parent link="sg_ziji_15_2" />
        <child link="xg_ziji_16_2" />
    </joint>
    <joint name="revolute_1" type="continuous">
        <origin xyz="-0.0255 0.0048 0" rpy="2.85901e-14 1.27833 3.47518e-14" />
        <axis xyz="0 -1 0" />
        <parent link="sg_ziji_15_3" />
        <child link="金属舵盘_驱动__v2_3" />
    </joint>
    <joint name="revolute_1_1" type="continuous">
        <origin xyz="-0.029 -0.0016 -0.01025" rpy="3.14159 1.54893 3.14159" />
        <axis xyz="0 -1 0" />
        <parent link="sg_ziji_15_2" />
        <child link="金属舵盘_驱动__v2_2" />
    </joint>
    <joint name="revolute_1_2" type="continuous">
        <origin xyz="1.38778e-17 -0.0045 -0.007" rpy="2.59898e-14 -1.54851 -2.36813e-14" />
        <axis xyz="-0 1 -0" />
        <parent link="金属舵盘_驱动__v2_1" />
        <child link="sg_ziji_15_1" />
    </joint>
    <joint name="revolute_1_3" type="continuous">
        <origin xyz="-0.029 -0.0016 -0.01025" rpy="1.30496e-15 1.28023e-15 2.06441e-16" />
        <axis xyz="0 -1 0" />
        <parent link="sg_ziji_15" />
        <child link="金属舵盘_驱动__v2" />
    </joint>
    <joint name="revolute_2" type="continuous">
        <origin xyz="-0.03275 0.0013 -0.01025" rpy="-1.00947e-14 0.24404 3.14159" />
        <axis xyz="-9.46633e-30 -1 0" />
        <parent link="xg_ziji_16_3" />
        <child link="金属舵盘_从动__v2_3" />
    </joint>
    <joint name="revolute_2_1" type="continuous">
        <origin xyz="0 1.73472e-18 0.0085" rpy="1.0713e-17 -7.20924e-17 -4.51028e-17" />
        <axis xyz="0 0 1" />
        <parent link="part_1_2" />
        <child link="part_2" />
    </joint>
    <joint name="revolute_2_2" type="continuous">
        <origin xyz="-0.0255 -0.0243 2.08167e-17" rpy="3.14159 -1.18466 4.70201e-16" />
        <axis xyz="-9.46633e-30 -1 0" />
        <parent link="xg_ziji_16_2" />
        <child link="金属舵盘_从动__v2_2" />
    </joint>
    <joint name="revolute_2_3" type="continuous">
        <origin xyz="-0.0255 -0.0243 -1.38778e-16" rpy="3.14159 -0.00410435 1.31685e-16" />
        <axis xyz="-9.46633e-30 -1 0" />
        <parent link="xg_ziji_16_1" />
        <child link="金属舵盘_从动__v2_1" />
    </joint>
    <joint name="revolute_2_4" type="continuous">
        <origin xyz="-0.0255 -0.0243 -6.93889e-18" rpy="1.9307e-16 -4.52763e-16 3.14159" />
        <axis xyz="-9.46633e-30 -1 0" />
        <parent link="xg_ziji_16" />
        <child link="金属舵盘_从动__v2" />
    </joint>
</robot>
